{
 "cells": [
  {
   "cell_type": "code",
   "execution_count": 9,
   "metadata": {
    "collapsed": true
   },
   "outputs": [],
   "source": [
    "an_apple = 27\n",
    "an_example = 42"
   ]
  },
  {
   "cell_type": "code",
   "execution_count": 8,
   "metadata": {
    "collapsed": true
   },
   "outputs": [],
   "source": [
    "b = [1,2,3]"
   ]
  },
  {
   "cell_type": "code",
   "execution_count": 7,
   "metadata": {
    "collapsed": true
   },
   "outputs": [],
   "source": [
    "import numpy as np"
   ]
  },
  {
   "cell_type": "code",
   "execution_count": 6,
   "metadata": {
    "collapsed": true
   },
   "outputs": [],
   "source": [
    "a = np.random.randn(100,100)"
   ]
  },
  {
   "cell_type": "code",
   "execution_count": 10,
   "metadata": {
    "collapsed": false
   },
   "outputs": [
    {
     "name": "stdout",
     "output_type": "stream",
     "text": [
      "10000 loops, best of 3: 74.7 Âµs per loop\n"
     ]
    }
   ],
   "source": [
    "%timeit np.dot(a,a)"
   ]
  },
  {
   "cell_type": "code",
   "execution_count": 11,
   "metadata": {
    "collapsed": false
   },
   "outputs": [
    {
     "name": "stdout",
     "output_type": "stream",
     "text": [
      "Once deleted, variables cannot be recovered. Proceed (y/[n])? y\n"
     ]
    }
   ],
   "source": [
    "%reset"
   ]
  },
  {
   "cell_type": "code",
   "execution_count": 12,
   "metadata": {
    "collapsed": true
   },
   "outputs": [],
   "source": [
    "%reset?"
   ]
  },
  {
   "cell_type": "code",
   "execution_count": 13,
   "metadata": {
    "collapsed": true
   },
   "outputs": [],
   "source": [
    "import pandas as pd\n",
    "import numpy as np\n",
    "import scipy as sp\n",
    "import plotly.plotly as py\n"
   ]
  },
  {
   "cell_type": "code",
   "execution_count": 17,
   "metadata": {
    "collapsed": false
   },
   "outputs": [
    {
     "ename": "PlotlyError",
     "evalue": "Aw, snap! You tried to use our API as the user 'Username', but the supplied API key doesn't match our records. You can view your API key at plot.ly/settings.\n\nYou're most likely getting this message because your local credentials file isn't synced with the Plotly server you're communicating with.\n\nGo to plot.ly/<language>/getting-started (e.g., plot.ly/python/getting-started) for more information.\n\nMake sure that you're logged in as Username.\n\nNeed help? Please try searching Plotly's <a href='http://stackoverflow.com/questions/tagged/plotly'>Stack Overflow channel</a>.",
     "output_type": "error",
     "traceback": [
      "\u001b[0;31m---------------------------------------------------------------------------\u001b[0m",
      "\u001b[0;31mPlotlyError\u001b[0m                               Traceback (most recent call last)",
      "\u001b[0;32m<ipython-input-17-de1c0558e9f7>\u001b[0m in \u001b[0;36m<module>\u001b[0;34m()\u001b[0m\n\u001b[1;32m     10\u001b[0m \u001b[0;34m\u001b[0m\u001b[0m\n\u001b[1;32m     11\u001b[0m \u001b[0mtable\u001b[0m \u001b[0;34m=\u001b[0m \u001b[0mff\u001b[0m\u001b[0;34m.\u001b[0m\u001b[0mcreate_table\u001b[0m\u001b[0;34m(\u001b[0m\u001b[0mdf\u001b[0m\u001b[0;34m)\u001b[0m\u001b[0;34m\u001b[0m\u001b[0m\n\u001b[0;32m---> 12\u001b[0;31m \u001b[0mpy\u001b[0m\u001b[0;34m.\u001b[0m\u001b[0miplot\u001b[0m\u001b[0;34m(\u001b[0m\u001b[0mtable\u001b[0m\u001b[0;34m,\u001b[0m \u001b[0mfilename\u001b[0m\u001b[0;34m=\u001b[0m\u001b[0;34m'jupyter/table1'\u001b[0m\u001b[0;34m)\u001b[0m\u001b[0;34m\u001b[0m\u001b[0m\n\u001b[0m",
      "\u001b[0;32m/Library/Python/2.7/site-packages/plotly/plotly/plotly.pyc\u001b[0m in \u001b[0;36miplot\u001b[0;34m(figure_or_data, **plot_options)\u001b[0m\n\u001b[1;32m    150\u001b[0m     \u001b[0;32mif\u001b[0m \u001b[0;34m'auto_open'\u001b[0m \u001b[0;32mnot\u001b[0m \u001b[0;32min\u001b[0m \u001b[0mplot_options\u001b[0m\u001b[0;34m:\u001b[0m\u001b[0;34m\u001b[0m\u001b[0m\n\u001b[1;32m    151\u001b[0m         \u001b[0mplot_options\u001b[0m\u001b[0;34m[\u001b[0m\u001b[0;34m'auto_open'\u001b[0m\u001b[0;34m]\u001b[0m \u001b[0;34m=\u001b[0m \u001b[0mFalse\u001b[0m\u001b[0;34m\u001b[0m\u001b[0m\n\u001b[0;32m--> 152\u001b[0;31m     \u001b[0murl\u001b[0m \u001b[0;34m=\u001b[0m \u001b[0mplot\u001b[0m\u001b[0;34m(\u001b[0m\u001b[0mfigure_or_data\u001b[0m\u001b[0;34m,\u001b[0m \u001b[0;34m**\u001b[0m\u001b[0mplot_options\u001b[0m\u001b[0;34m)\u001b[0m\u001b[0;34m\u001b[0m\u001b[0m\n\u001b[0m\u001b[1;32m    153\u001b[0m \u001b[0;34m\u001b[0m\u001b[0m\n\u001b[1;32m    154\u001b[0m     \u001b[0;32mif\u001b[0m \u001b[0misinstance\u001b[0m\u001b[0;34m(\u001b[0m\u001b[0mfigure_or_data\u001b[0m\u001b[0;34m,\u001b[0m \u001b[0mdict\u001b[0m\u001b[0;34m)\u001b[0m\u001b[0;34m:\u001b[0m\u001b[0;34m\u001b[0m\u001b[0m\n",
      "\u001b[0;32m/Library/Python/2.7/site-packages/plotly/plotly/plotly.pyc\u001b[0m in \u001b[0;36mplot\u001b[0;34m(figure_or_data, validate, **plot_options)\u001b[0m\n\u001b[1;32m    239\u001b[0m \u001b[0;34m\u001b[0m\u001b[0m\n\u001b[1;32m    240\u001b[0m     \u001b[0mplot_options\u001b[0m \u001b[0;34m=\u001b[0m \u001b[0m_plot_option_logic\u001b[0m\u001b[0;34m(\u001b[0m\u001b[0mplot_options\u001b[0m\u001b[0;34m)\u001b[0m\u001b[0;34m\u001b[0m\u001b[0m\n\u001b[0;32m--> 241\u001b[0;31m     \u001b[0mres\u001b[0m \u001b[0;34m=\u001b[0m \u001b[0m_send_to_plotly\u001b[0m\u001b[0;34m(\u001b[0m\u001b[0mfigure\u001b[0m\u001b[0;34m,\u001b[0m \u001b[0;34m**\u001b[0m\u001b[0mplot_options\u001b[0m\u001b[0;34m)\u001b[0m\u001b[0;34m\u001b[0m\u001b[0m\n\u001b[0m\u001b[1;32m    242\u001b[0m \u001b[0;34m\u001b[0m\u001b[0m\n\u001b[1;32m    243\u001b[0m     \u001b[0;32mif\u001b[0m \u001b[0mres\u001b[0m\u001b[0;34m[\u001b[0m\u001b[0;34m'error'\u001b[0m\u001b[0;34m]\u001b[0m \u001b[0;34m==\u001b[0m \u001b[0;34m''\u001b[0m\u001b[0;34m:\u001b[0m\u001b[0;34m\u001b[0m\u001b[0m\n",
      "\u001b[0;32m/Library/Python/2.7/site-packages/plotly/plotly/plotly.pyc\u001b[0m in \u001b[0;36m_send_to_plotly\u001b[0;34m(figure, **plot_options)\u001b[0m\n\u001b[1;32m   1436\u001b[0m \u001b[0;34m\u001b[0m\u001b[0m\n\u001b[1;32m   1437\u001b[0m     \u001b[0;32mif\u001b[0m \u001b[0;34m'error'\u001b[0m \u001b[0;32min\u001b[0m \u001b[0mr\u001b[0m \u001b[0;32mand\u001b[0m \u001b[0mr\u001b[0m\u001b[0;34m[\u001b[0m\u001b[0;34m'error'\u001b[0m\u001b[0;34m]\u001b[0m \u001b[0;34m!=\u001b[0m \u001b[0;34m''\u001b[0m\u001b[0;34m:\u001b[0m\u001b[0;34m\u001b[0m\u001b[0m\n\u001b[0;32m-> 1438\u001b[0;31m         \u001b[0;32mraise\u001b[0m \u001b[0mexceptions\u001b[0m\u001b[0;34m.\u001b[0m\u001b[0mPlotlyError\u001b[0m\u001b[0;34m(\u001b[0m\u001b[0mr\u001b[0m\u001b[0;34m[\u001b[0m\u001b[0;34m'error'\u001b[0m\u001b[0;34m]\u001b[0m\u001b[0;34m)\u001b[0m\u001b[0;34m\u001b[0m\u001b[0m\n\u001b[0m\u001b[1;32m   1439\u001b[0m \u001b[0;34m\u001b[0m\u001b[0m\n\u001b[1;32m   1440\u001b[0m     \u001b[0;31m# Check if the url needs a secret key\u001b[0m\u001b[0;34m\u001b[0m\u001b[0;34m\u001b[0m\u001b[0m\n",
      "\u001b[0;31mPlotlyError\u001b[0m: Aw, snap! You tried to use our API as the user 'Username', but the supplied API key doesn't match our records. You can view your API key at plot.ly/settings.\n\nYou're most likely getting this message because your local credentials file isn't synced with the Plotly server you're communicating with.\n\nGo to plot.ly/<language>/getting-started (e.g., plot.ly/python/getting-started) for more information.\n\nMake sure that you're logged in as Username.\n\nNeed help? Please try searching Plotly's <a href='http://stackoverflow.com/questions/tagged/plotly'>Stack Overflow channel</a>."
     ]
    }
   ],
   "source": [
    "import plotly.plotly as py\n",
    "from plotly.tools import FigureFactory as ff\n",
    "\n",
    "import pandas as pd\n",
    "\n",
    "\n",
    "py.sign_in('username', 'api_key')\n",
    "\n",
    "df = pd.read_csv(\"https://raw.githubusercontent.com/plotly/datasets/master/school_earnings.csv\")\n",
    "\n",
    "table = ff.create_table(df)\n",
    "py.iplot(table, filename='jupyter/table1')"
   ]
  },
  {
   "cell_type": "code",
   "execution_count": null,
   "metadata": {
    "collapsed": true
   },
   "outputs": [],
   "source": []
  }
 ],
 "metadata": {
  "kernelspec": {
   "display_name": "Python 2",
   "language": "python",
   "name": "python2"
  },
  "language_info": {
   "codemirror_mode": {
    "name": "ipython",
    "version": 2
   },
   "file_extension": ".py",
   "mimetype": "text/x-python",
   "name": "python",
   "nbconvert_exporter": "python",
   "pygments_lexer": "ipython2",
   "version": "2.7.10"
  }
 },
 "nbformat": 4,
 "nbformat_minor": 2
}
